Process Process-4:
Traceback (most recent call last):
  File "/Library/Frameworks/Python.framework/Versions/3.12/lib/python3.12/multiprocessing/process.py", line 314, in _bootstrap
    self.run()
  File "/Library/Frameworks/Python.framework/Versions/3.12/lib/python3.12/multiprocessing/process.py", line 108, in run
    self._target(*self._args, **self._kwargs)
  File "/Users/tadeatobatele/Documents/UniStuff/CS351 Project/code/PoSBlockchain/code_node2/Blockchain/Backend/core/network/syncManager.py", line 44, in spinUpServer
    self.conn, self.addr = self.server.acceptConnection()
                           ^^^^^^^^^^^^^^^^^^^^^^^^^^^^^^
  File "/Users/tadeatobatele/Documents/UniStuff/CS351 Project/code/PoSBlockchain/code_node2/Blockchain/Backend/core/network/connection.py", line 28, in acceptConnection
    self.conn, self.addr = self.server.accept()
                           ^^^^^^^^^^^^^^^^^^^^
  File "/Library/Frameworks/Python.framework/Versions/3.12/lib/python3.12/socket.py", line 295, in accept
    fd, addr = self._accept()
               ^^^^^^^^^^^^^^
KeyboardInterrupt
Exception ignored in: <function BaseDB.__del__ at 0x10191d120>
Traceback (most recent call last):
  File "/Users/tadeatobatele/Documents/UniStuff/CS351 Project/code/PoSBlockchain/code_node2/Blockchain/Backend/core/database/db.py", line 82, in __del__
    self.conn.close()
sqlite3.ProgrammingError: SQLite objects created in a thread can only be used in that same thread. The object was created in thread id 6191149056 and this is thread id 8227496192.
